[[
  {
    "name": "postgres.connect",
    "service": "postgres",
    "resource": "postgres.connect",
    "trace_id": 0,
    "span_id": 1,
    "parent_id": 0,
    "type": "sql",
    "meta": {
      "_dd.base_service": "",
      "_dd.p.dm": "-0",
      "component": "asyncpg",
      "db.name": "postgres",
      "db.system": "postgresql",
      "db.user": "postgres",
      "language": "python",
      "out.host": "127.0.0.1",
      "runtime-id": "ed7e8c2b2f2941df82375dfe28f4da8c",
      "span.kind": "client"
    },
    "metrics": {
      "_dd.top_level": 1,
      "_dd.tracer_kr": 1.0,
      "_sampling_priority_v1": 1,
      "network.destination.port": 5432,
      "process_id": 25714
    },
    "duration": 3872958,
    "start": 1692706986511852881
  }],
[
  {
    "name": "postgres.query",
    "service": "postgres",
    "resource": "malformed; query;dfaskjfd",
    "trace_id": 1,
    "span_id": 1,
    "parent_id": 0,
    "type": "sql",
    "error": 1,
    "meta": {
      "_dd.base_service": "",
      "_dd.p.dm": "-0",
      "component": "asyncpg",
      "db.name": "postgres",
      "db.system": "postgresql",
      "db.user": "postgres",
      "error.message": "syntax error at or near \"malformed\"",
      "error.stack": "Traceback (most recent call last):\n  File \"/root/project/ddtrace/contrib/asyncpg/patch.py\", line 114, in _traced_query\n    return await method(*args, **kwargs)\n  File \"asyncpg/protocol/protocol.pyx\", line 336, in query\nasyncpg.exceptions.PostgresSyntaxError: syntax error at or near \"malformed\"\n",
      "error.type": "asyncpg.exceptions.PostgresSyntaxError",
      "language": "python",
      "out.host": "127.0.0.1",
      "runtime-id": "ed7e8c2b2f2941df82375dfe28f4da8c",
      "span.kind": "client"
    },
    "metrics": {
      "_dd.measured": 1,
      "_dd.top_level": 1,
      "_dd.tracer_kr": 1.0,
      "_sampling_priority_v1": 1,
      "network.destination.port": 5432,
      "process_id": 25714
    },
    "duration": 1039541,
    "start": 1692706986516239256
  }]]
