[[
  {
    "name": "google_genai.request",
    "service": "tests.contrib.google_genai",
    "resource": "AsyncModels.generate_content",
    "trace_id": 0,
    "span_id": 1,
    "parent_id": 0,
    "type": "",
    "error": 1,
    "meta": {
      "_dd.p.dm": "-0",
      "_dd.p.tid": "685da0ad00000000",
      "error.message": "AsyncModels.generate_content() got an unexpected keyword argument 'not_an_argument'",
      "error.stack": "Traceback (most recent call last):\n  File \"/Users/max.zhang/dd-trace-py/ddtrace/contrib/internal/google_genai/patch.py\", line 64, in traced_async_generate\n    resp = await func(*args, **kwargs)\n                 ^^^^^^^^^^^^^^^^^^^^^\nTypeError: AsyncModels.generate_content() got an unexpected keyword argument 'not_an_argument'\n",
      "error.type": "builtins.TypeError",
      "google_genai.request.model": "gemini-2.0-flash-001",
      "google_genai.request.provider": "google",
      "language": "python",
      "runtime-id": "41bef93530d8400d9a9c034c7c4d5c43"
    },
    "metrics": {
      "_dd.measured": 1,
      "_dd.top_level": 1,
      "_dd.tracer_kr": 1.0,
      "_sampling_priority_v1": 1,
      "process_id": 29950
    },
    "duration": 128000,
    "start": 1750966445748723000
  }]]
